<?xml version="1.0" ?>
<!-- =================================================================================== -->
<!-- |    This document was autogenerated by xacro from micro.xacro                    | -->
<!-- |    EDITING THIS FILE BY HAND IS NOT RECOMMENDED                                 | -->
<!-- =================================================================================== -->
<robot name="spot_micro">
  <!-- Define materials -->
  <material name="yellow">
    <color rgba="0.92 0.83 0.0 1"/>
  </material>
  <material name="black">
    <color rgba="0.1 0.1 0.1 1"/>
  </material>
  <material name="grey">
    <color rgba="0.6 0.6 0.6 1"/>
  </material>
  <!-- Macros -->
  <!-- Robot Body -->
  <link name="base_link">
    <visual>
      <geometry>
        <mesh filename="package://model_sentra/urdf/stl/mainbody.stl" scale="0.001 0.001 0.001"/>
      </geometry>
      <material name="black"/>
      <origin rpy="0 0 0" xyz="-0.042 -0.055 -0.010"/>
    </visual>
    <collision>
      <geometry>
        <box size="0.14 0.11 0.07"/>
      </geometry>
      <origin rpy="0 0 0" xyz="0 0 0"/>
    </collision>
    <inertial>
      <mass value="2.80"/>
      <inertia ixx="100" ixy="0" ixz="0" iyy="100" iyz="0" izz="100"/>
    </inertial>
  </link>
  <!-- Lidar Backpack -->
  <link name="lidar_link">
    <visual>
      <geometry>
        <mesh filename="package://model_sentra/urdf/stl/rplidar_main.STL" scale="0.001 0.001 0.001"/>
      </geometry>
      <material name="black"/>
      <origin rpy="1.57075 0 0" xyz="-0.03425 0.03585 0"/>
    </visual>
    <collision>
      <geometry>
        <box size="0.0985 0.0577 0.07"/>
      </geometry>
      <origin rpy="0 0 0" xyz="0 0 0"/>
    </collision>
    <inertial>
      <mass value="0.50"/>
      <inertia ixx="100" ixy="0" ixz="0" iyy="100" iyz="0" izz="100"/>
    </inertial>
  </link>
  <joint name="base_lidar" type="fixed">
    <parent link="base_link"/>
    <child link="lidar_link"/>
    <origin xyz="0 0 0.035"/>
  </joint>
  <!-- Rear link -->
  <link name="rear_link">
    <visual>
      <geometry>
        <mesh filename="package://model_sentra/urdf/stl/backpart.stl" scale="0.001 0.001 0.001"/>
      </geometry>
      <origin rpy="0 0 3.14159" xyz="0.04 0.055 -0.010"/>
      <material name="yellow"/>
    </visual>
    <collision>
      <geometry>
        <box size="0.04 0.11 0.07"/>
      </geometry>
      <origin rpy="0 0 0" xyz="0.135 0 0"/>
    </collision>
    <inertial>
      <mass value="0.20"/>
      <inertia ixx="100" ixy="0" ixz="0" iyy="100" iyz="0" izz="100"/>
    </inertial>
  </link>
  <!-- Rear joint -->
  <joint name="base_rear" type="fixed">
    <parent link="base_link"/>
    <child link="rear_link"/>
  </joint>
  <!-- Front link -->
  <link name="front_link">
    <visual>
      <geometry>
        <mesh filename="package://model_sentra/urdf/stl/frontpart.stl" scale="0.001 0.001 0.001"/>
      </geometry>
      <origin rpy="0 0 3.14159" xyz="0.040 0.055 -0.010"/>
      <material name="yellow"/>
    </visual>
    <collision>
      <geometry>
        <box size="0.058 0.11 0.07"/>
      </geometry>
      <origin rpy="0 0 0" xyz="-0.145 0 0"/>
    </collision>
    <inertial>
      <mass value="0.20"/>
      <inertia ixx="100" ixy="0" ixz="0" iyy="100" iyz="0" izz="100"/>
    </inertial>
  </link>
  <!-- Front joint -->
  <joint name="base_front" type="fixed">
    <parent link="base_link"/>
    <child link="front_link"/>
  </joint>
  <link name="front_left_shoulder_link">
    <visual>
      <geometry>
        <mesh filename="package://model_sentra/urdf/stl/lshoulder.stl" scale="0.001 0.001 0.001"/>
      </geometry>
      <origin rpy="0 0 3.14159" xyz="0.135 0.015 -0.01"/>
      <material name="black"/>
    </visual>
    <collision>
      <geometry>
        <box size="0.044 0.038 0.07"/>
      </geometry>
      <origin rpy="0 0 0" xyz="0 0 0"/>
    </collision>
    <inertial>
      <mass value="0.10"/>
      <inertia ixx="100" ixy="0" ixz="0" iyy="100" iyz="0" izz="100"/>
    </inertial>
  </link>
  <link name="front_left_leg_link_cover">
    <visual>
      <geometry>
        <mesh filename="package://model_sentra/urdf/stl/larm_cover.stl" scale="0.001 0.001 0.001"/>
      </geometry>
      <origin rpy="0 -0.139 3.14159" xyz="0.130 -0.040 -0.025"/>
      <material name="yellow"/>
    </visual>
  </link>
  <link name="front_left_leg_link">
    <visual>
      <geometry>
        <mesh filename="package://model_sentra/urdf/stl/larm.stl" scale="0.001 0.001 0.001"/>
      </geometry>
      <origin rpy="0 -0.139 3.14159" xyz="0.130 -0.040 -0.025"/>
      <material name="black"/>
    </visual>
    <collision>
      <origin rpy="0.0 0.0 0.0" xyz="0.0 0.0 -0.050"/>
      <geometry>
        <box size="0.028 0.036 0.1075"/>
      </geometry>
    </collision>
    <inertial>
      <mass value="0.15"/>
      <inertia ixx="1000" ixy="0" ixz="0" iyy="1000" iyz="0" izz="1000"/>
    </inertial>
  </link>
  <link name="front_left_foot_link">
    <visual>
      <geometry>
        <mesh filename="package://model_sentra/urdf/stl/lfoot.stl" scale="0.001 0.001 0.001"/>
      </geometry>
      <origin rpy="0 0 3.14159" xyz="0.120 -0.04 0.1"/>
      <material name="black"/>
    </visual>
    <collision>
      <geometry>
        <box size="0.026 0.020 0.13"/>
      </geometry>
      <origin rpy="0.0 0.0 0.0" xyz="0.0 0.0 -0.050"/>
    </collision>
    <inertial>
      <mass value="0.1"/>
      <inertia ixx="1000" ixy="0" ixz="0" iyy="1000" iyz="0" izz="1000"/>
    </inertial>
  </link>
  <link name="front_left_toe_link">
    <visual>
      <geometry>
        <mesh filename="package://model_sentra/urdf/stl/foot.stl" scale="0.001 0.001 0.001"/>
      </geometry>
      <origin rpy="0 -0.40010 3.14159" xyz="0.00 0.01 0.015"/>
      <material name="grey"/>
    </visual>
    <collision>
      <geometry>
        <sphere radius="0.02"/>
      </geometry>
      <origin rpy="0 0 0" xyz="0 0 0.02"/>
      <contact_coefficients mu="1.1"/>
    </collision>
    <inertial>
      <mass value="0.05"/>
      <inertia ixx="1000" ixy="0" ixz="0" iyy="1000" iyz="0" izz="1000"/>
    </inertial>
  </link>
  <joint name="front_left_shoulder" type="revolute">
    <parent link="base_link"/>
    <child link="front_left_shoulder_link"/>
    <axis xyz="1 0 0"/>
    <origin rpy="0 0 0" xyz="0.093 0.039 0"/>
    <limit effort="1000.0" lower="-0.548" upper="0.548" velocity="0.7"/>
    <dynamics damping="0.0" friction="0.5"/>
  </joint>
  <joint name="front_left_leg" type="revolute">
    <parent link="front_left_shoulder_link"/>
    <child link="front_left_leg_link"/>
    <axis xyz="0 1 0"/>
    <origin rpy="0 0 0" xyz="0 0.055 0"/>
    <limit effort="1000.0" lower="-2.666" upper="1.548" velocity="0.5"/>
    <dynamics damping="0.0" friction="0.0"/>
  </joint>
  <joint name="front_left_leg_cover_joint" type="fixed">
    <parent link="front_left_leg_link"/>
    <child link="front_left_leg_link_cover"/>
    <origin xyz="0 0 0"/>
  </joint>
  <joint name="front_left_foot" type="revolute">
    <parent link="front_left_leg_link"/>
    <child link="front_left_foot_link"/>
    <axis xyz="0 1 0"/>
    <origin rpy="0 0 0" xyz="0 0 -0.1075"/>
    <limit effort="1000.0" lower="-2.6" upper="0.1" velocity="0.5"/>
    <dynamics damping="0.0" friction="0.5"/>
  </joint>
  <joint name="front_left_toe" type="fixed">
    <parent link="front_left_foot_link"/>
    <child link="front_left_toe_link"/>
    <origin xyz="0 0 -0.13"/>
  </joint>
  <link name="front_right_shoulder_link">
    <visual>
      <geometry>
        <mesh filename="package://model_sentra/urdf/stl/rshoulder.stl" scale="0.001 0.001 0.001"/>
      </geometry>
      <origin rpy="0 0 3.14159" xyz="0.135 0.095 -0.01"/>
      <material name="black"/>
    </visual>
    <collision>
      <geometry>
        <box size="0.044 0.038 0.07"/>
      </geometry>
      <origin rpy="0 0 0" xyz="0 0 0"/>
    </collision>
    <inertial>
      <mass value="0.10"/>
      <inertia ixx="100" ixy="0" ixz="0" iyy="100" iyz="0" izz="100"/>
    </inertial>
  </link>
  <link name="front_right_leg_link_cover">
    <visual>
      <geometry>
        <mesh filename="package://model_sentra/urdf/stl/rarm_cover.stl" scale="0.001 0.001 0.001"/>
      </geometry>
      <origin rpy="0 -0.139 3.14159" xyz="0.130 0.15 -0.025"/>
      <material name="yellow"/>
    </visual>
  </link>
  <link name="front_right_leg_link">
    <visual>
      <geometry>
        <mesh filename="package://model_sentra/urdf/stl/rarm.stl" scale="0.001 0.001 0.001"/>
      </geometry>
      <origin rpy="0 -0.139 3.14159" xyz="0.130 0.15 -0.025"/>
      <material name="black"/>
    </visual>
    <collision>
      <origin rpy="0.0 0.0 0.0" xyz="0.0 0.0 -0.050"/>
      <geometry>
        <box size="0.028 0.036 0.1075"/>
      </geometry>
    </collision>
    <inertial>
      <mass value="0.15"/>
      <inertia ixx="1000" ixy="0" ixz="0" iyy="1000" iyz="0" izz="1000"/>
    </inertial>
  </link>
  <link name="front_right_foot_link">
    <visual>
      <geometry>
        <mesh filename="package://model_sentra/urdf/stl/rfoot.stl" scale="0.001 0.001 0.001"/>
      </geometry>
      <origin rpy="0 0 3.14159" xyz="0.120 0.15 0.1"/>
      <material name="black"/>
    </visual>
    <collision>
      <geometry>
        <box size="0.026 0.020 0.13"/>
      </geometry>
      <origin rpy="0.0 0.0 0.0" xyz="0.0 0.0 -0.050"/>
    </collision>
    <inertial>
      <mass value="0.1"/>
      <inertia ixx="1000" ixy="0" ixz="0" iyy="1000" iyz="0" izz="1000"/>
    </inertial>
  </link>
  <link name="front_right_toe_link">
    <visual>
      <geometry>
        <mesh filename="package://model_sentra/urdf/stl/foot.stl" scale="0.001 0.001 0.001"/>
      </geometry>
      <origin rpy="0 -0.40010 3.14159" xyz="0.00 0.01 0.015"/>
      <material name="grey"/>
    </visual>
    <collision>
      <geometry>
        <sphere radius="0.02"/>
      </geometry>
      <origin rpy="0 0 0" xyz="0 0 0.02"/>
      <contact_coefficients mu="1.1"/>
    </collision>
    <inertial>
      <mass value="0.05"/>
      <inertia ixx="1000" ixy="0" ixz="0" iyy="1000" iyz="0" izz="1000"/>
    </inertial>
  </link>
  <joint name="front_right_shoulder" type="revolute">
    <parent link="base_link"/>
    <child link="front_right_shoulder_link"/>
    <axis xyz="1 0 0"/>
    <origin rpy="0 0 0" xyz="0.093 -0.039 0"/>
    <limit effort="1000.0" lower="-0.548" upper="0.548" velocity="0.7"/>
    <dynamics damping="0.0" friction="0.5"/>
  </joint>
  <joint name="front_right_leg" type="revolute">
    <parent link="front_right_shoulder_link"/>
    <child link="front_right_leg_link"/>
    <axis xyz="0 1 0"/>
    <origin rpy="0 0 0" xyz="0 -0.055 0"/>
    <limit effort="1000.0" lower="-2.666" upper="1.548" velocity="0.5"/>
    <dynamics damping="0.0" friction="0.0"/>
  </joint>
  <joint name="front_right_leg_cover_joint" type="fixed">
    <parent link="front_right_leg_link"/>
    <child link="front_right_leg_link_cover"/>
    <origin xyz="0 0 0"/>
  </joint>
  <joint name="front_right_foot" type="revolute">
    <parent link="front_right_leg_link"/>
    <child link="front_right_foot_link"/>
    <axis xyz="0 1 0"/>
    <origin rpy="0 0 0" xyz="0 0 -0.1075"/>
    <limit effort="1000.0" lower="-2.6" upper="0.1" velocity="0.5"/>
    <dynamics damping="0.0" friction="0.5"/>
  </joint>
  <joint name="front_right_toe" type="fixed">
    <parent link="front_right_foot_link"/>
    <child link="front_right_toe_link"/>
    <origin xyz="0 0 -0.13"/>
  </joint>
  <link name="rear_left_shoulder_link">
    <visual>
      <geometry>
        <mesh filename="package://model_sentra/urdf/stl/lshoulder.stl" scale="0.001 0.001 0.001"/>
      </geometry>
      <origin rpy="0 0 3.14159" xyz="0.135 0.015 -0.01"/>
      <material name="black"/>
    </visual>
    <collision>
      <geometry>
        <box size="0.044 0.038 0.07"/>
      </geometry>
      <origin rpy="0 0 0" xyz="0 0 0"/>
    </collision>
    <inertial>
      <mass value="0.10"/>
      <inertia ixx="100" ixy="0" ixz="0" iyy="100" iyz="0" izz="100"/>
    </inertial>
  </link>
  <link name="rear_left_leg_link_cover">
    <visual>
      <geometry>
        <mesh filename="package://model_sentra/urdf/stl/larm_cover.stl" scale="0.001 0.001 0.001"/>
      </geometry>
      <origin rpy="0 -0.139 3.14159" xyz="0.130 -0.040 -0.025"/>
      <material name="yellow"/>
    </visual>
  </link>
  <link name="rear_left_leg_link">
    <visual>
      <geometry>
        <mesh filename="package://model_sentra/urdf/stl/larm.stl" scale="0.001 0.001 0.001"/>
      </geometry>
      <origin rpy="0 -0.139 3.14159" xyz="0.130 -0.040 -0.025"/>
      <material name="black"/>
    </visual>
    <collision>
      <origin rpy="0.0 0.0 0.0" xyz="0.0 0.0 -0.050"/>
      <geometry>
        <box size="0.028 0.036 0.1075"/>
      </geometry>
    </collision>
    <inertial>
      <mass value="0.15"/>
      <inertia ixx="1000" ixy="0" ixz="0" iyy="1000" iyz="0" izz="1000"/>
    </inertial>
  </link>
  <link name="rear_left_foot_link">
    <visual>
      <geometry>
        <mesh filename="package://model_sentra/urdf/stl/lfoot.stl" scale="0.001 0.001 0.001"/>
      </geometry>
      <origin rpy="0 0 3.14159" xyz="0.120 -0.04 0.1"/>
      <material name="black"/>
    </visual>
    <collision>
      <geometry>
        <box size="0.026 0.020 0.13"/>
      </geometry>
      <origin rpy="0.0 0.0 0.0" xyz="0.0 0.0 -0.050"/>
    </collision>
    <inertial>
      <mass value="0.1"/>
      <inertia ixx="1000" ixy="0" ixz="0" iyy="1000" iyz="0" izz="1000"/>
    </inertial>
  </link>
  <link name="rear_left_toe_link">
    <visual>
      <geometry>
        <mesh filename="package://model_sentra/urdf/stl/foot.stl" scale="0.001 0.001 0.001"/>
      </geometry>
      <origin rpy="0 -0.40010 3.14159" xyz="0.00 0.01 0.015"/>
      <material name="grey"/>
    </visual>
    <collision>
      <geometry>
        <sphere radius="0.02"/>
      </geometry>
      <origin rpy="0 0 0" xyz="0 0 0.02"/>
      <contact_coefficients mu="1.1"/>
    </collision>
    <inertial>
      <mass value="0.05"/>
      <inertia ixx="1000" ixy="0" ixz="0" iyy="1000" iyz="0" izz="1000"/>
    </inertial>
  </link>
  <joint name="rear_left_shoulder" type="revolute">
    <parent link="base_link"/>
    <child link="rear_left_shoulder_link"/>
    <axis xyz="1 0 0"/>
    <origin rpy="0 0 0" xyz="-0.093 0.039 0"/>
    <limit effort="1000.0" lower="-0.548" upper="0.548" velocity="0.7"/>
    <dynamics damping="0.0" friction="0.5"/>
  </joint>
  <joint name="rear_left_leg" type="revolute">
    <parent link="rear_left_shoulder_link"/>
    <child link="rear_left_leg_link"/>
    <axis xyz="0 1 0"/>
    <origin rpy="0 0 0" xyz="0 0.055 0"/>
    <limit effort="1000.0" lower="-2.666" upper="1.548" velocity="0.5"/>
    <dynamics damping="0.0" friction="0.0"/>
  </joint>
  <joint name="rear_left_leg_cover_joint" type="fixed">
    <parent link="rear_left_leg_link"/>
    <child link="rear_left_leg_link_cover"/>
    <origin xyz="0 0 0"/>
  </joint>
  <joint name="rear_left_foot" type="revolute">
    <parent link="rear_left_leg_link"/>
    <child link="rear_left_foot_link"/>
    <axis xyz="0 1 0"/>
    <origin rpy="0 0 0" xyz="0 0 -0.1075"/>
    <limit effort="1000.0" lower="-2.6" upper="0.1" velocity="0.5"/>
    <dynamics damping="0.0" friction="0.5"/>
  </joint>
  <joint name="rear_left_toe" type="fixed">
    <parent link="rear_left_foot_link"/>
    <child link="rear_left_toe_link"/>
    <origin xyz="0 0 -0.13"/>
  </joint>
  <link name="rear_right_shoulder_link">
    <visual>
      <geometry>
        <mesh filename="package://model_sentra/urdf/stl/rshoulder.stl" scale="0.001 0.001 0.001"/>
      </geometry>
      <origin rpy="0 0 3.14159" xyz="0.135 0.095 -0.01"/>
      <material name="black"/>
    </visual>
    <collision>
      <geometry>
        <box size="0.044 0.038 0.07"/>
      </geometry>
      <origin rpy="0 0 0" xyz="0 0 0"/>
    </collision>
    <inertial>
      <mass value="0.10"/>
      <inertia ixx="100" ixy="0" ixz="0" iyy="100" iyz="0" izz="100"/>
    </inertial>
  </link>
  <link name="rear_right_leg_link_cover">
    <visual>
      <geometry>
        <mesh filename="package://model_sentra/urdf/stl/rarm_cover.stl" scale="0.001 0.001 0.001"/>
      </geometry>
      <origin rpy="0 -0.139 3.14159" xyz="0.130 0.15 -0.025"/>
      <material name="yellow"/>
    </visual>
  </link>
  <link name="rear_right_leg_link">
    <visual>
      <geometry>
        <mesh filename="package://model_sentra/urdf/stl/rarm.stl" scale="0.001 0.001 0.001"/>
      </geometry>
      <origin rpy="0 -0.139 3.14159" xyz="0.130 0.15 -0.025"/>
      <material name="black"/>
    </visual>
    <collision>
      <origin rpy="0.0 0.0 0.0" xyz="0.0 0.0 -0.050"/>
      <geometry>
        <box size="0.028 0.036 0.1075"/>
      </geometry>
    </collision>
    <inertial>
      <mass value="0.15"/>
      <inertia ixx="1000" ixy="0" ixz="0" iyy="1000" iyz="0" izz="1000"/>
    </inertial>
  </link>
  <link name="rear_right_foot_link">
    <visual>
      <geometry>
        <mesh filename="package://model_sentra/urdf/stl/rfoot.stl" scale="0.001 0.001 0.001"/>
      </geometry>
      <origin rpy="0 0 3.14159" xyz="0.120 0.15 0.1"/>
      <material name="black"/>
    </visual>
    <collision>
      <geometry>
        <box size="0.026 0.020 0.13"/>
      </geometry>
      <origin rpy="0.0 0.0 0.0" xyz="0.0 0.0 -0.050"/>
    </collision>
    <inertial>
      <mass value="0.1"/>
      <inertia ixx="1000" ixy="0" ixz="0" iyy="1000" iyz="0" izz="1000"/>
    </inertial>
  </link>
  <link name="rear_right_toe_link">
    <visual>
      <geometry>
        <mesh filename="package://model_sentra/urdf/stl/foot.stl" scale="0.001 0.001 0.001"/>
      </geometry>
      <origin rpy="0 -0.40010 3.14159" xyz="0.00 0.01 0.015"/>
      <material name="grey"/>
    </visual>
    <collision>
      <geometry>
        <sphere radius="0.02"/>
      </geometry>
      <origin rpy="0 0 0" xyz="0 0 0.02"/>
      <contact_coefficients mu="1.1"/>
    </collision>
    <inertial>
      <mass value="0.05"/>
      <inertia ixx="1000" ixy="0" ixz="0" iyy="1000" iyz="0" izz="1000"/>
    </inertial>
  </link>
  <joint name="rear_right_shoulder" type="revolute">
    <parent link="base_link"/>
    <child link="rear_right_shoulder_link"/>
    <axis xyz="1 0 0"/>
    <origin rpy="0 0 0" xyz="-0.093 -0.039 0"/>
    <limit effort="1000.0" lower="-0.548" upper="0.548" velocity="0.7"/>
    <dynamics damping="0.0" friction="0.5"/>
  </joint>
  <joint name="rear_right_leg" type="revolute">
    <parent link="rear_right_shoulder_link"/>
    <child link="rear_right_leg_link"/>
    <axis xyz="0 1 0"/>
    <origin rpy="0 0 0" xyz="0 -0.055 0"/>
    <limit effort="1000.0" lower="-2.666" upper="1.548" velocity="0.5"/>
    <dynamics damping="0.0" friction="0.0"/>
  </joint>
  <joint name="rear_right_leg_cover_joint" type="fixed">
    <parent link="rear_right_leg_link"/>
    <child link="rear_right_leg_link_cover"/>
    <origin xyz="0 0 0"/>
  </joint>
  <joint name="rear_right_foot" type="revolute">
    <parent link="rear_right_leg_link"/>
    <child link="rear_right_foot_link"/>
    <axis xyz="0 1 0"/>
    <origin rpy="0 0 0" xyz="0 0 -0.1075"/>
    <limit effort="1000.0" lower="-2.6" upper="0.1" velocity="0.5"/>
    <dynamics damping="0.0" friction="0.5"/>
  </joint>
  <joint name="rear_right_toe" type="fixed">
    <parent link="rear_right_foot_link"/>
    <child link="rear_right_toe_link"/>
    <origin xyz="0 0 -0.13"/>
  </joint>
  <transmission name="front_left_shoulder_trans">
    <type>transmission_interface/SimpleTransmission</type>
    <actuator>
      <name>front_left_shoulder_motor</name>
      <mechanicalReduction>1</mechanicalReduction>
    </actuator>
    <joint>
      <name>front_left_shoulder</name>
      <hardwareInterface>hardware_interface/Effort</hardwareInterface>
    </joint>
  </transmission>
  <transmission name="front_left_leg_trans">
    <type>transmission_interface/SimpleTransmission</type>
    <actuator>
      <name>front_left_leg_motor</name>
      <mechanicalReduction>1</mechanicalReduction>
    </actuator>
    <joint>
      <name>front_left_leg</name>
      <hardwareInterface>hardware_interface/Effort</hardwareInterface>
    </joint>
  </transmission>
  <transmission name="front_left_foot_trans">
    <type>transmission_interface/SimpleTransmission</type>
    <actuator>
      <name>front_left_foot_motor</name>
      <mechanicalReduction>1</mechanicalReduction>
    </actuator>
    <joint>
      <name>front_left_foot</name>
      <hardwareInterface>hardware_interface/Effort</hardwareInterface>
    </joint>
  </transmission>
  <transmission name="front_right_shoulder_trans">
    <type>transmission_interface/SimpleTransmission</type>
    <actuator>
      <name>front_right_shoulder_motor</name>
      <mechanicalReduction>1</mechanicalReduction>
    </actuator>
    <joint>
      <name>front_right_shoulder</name>
      <hardwareInterface>hardware_interface/Effort</hardwareInterface>
    </joint>
  </transmission>
  <transmission name="front_right_leg_trans">
    <type>transmission_interface/SimpleTransmission</type>
    <actuator>
      <name>front_right_leg_motor</name>
      <mechanicalReduction>1</mechanicalReduction>
    </actuator>
    <joint>
      <name>front_right_leg</name>
      <hardwareInterface>hardware_interface/Effort</hardwareInterface>
    </joint>
  </transmission>
  <transmission name="front_right_foot_trans">
    <type>transmission_interface/SimpleTransmission</type>
    <actuator>
      <name>front_right_foot_motor</name>
      <mechanicalReduction>1</mechanicalReduction>
    </actuator>
    <joint>
      <name>front_right_foot</name>
      <hardwareInterface>hardware_interface/Effort</hardwareInterface>
    </joint>
  </transmission>
  <transmission name="rear_left_shoulder_trans">
    <type>transmission_interface/SimpleTransmission</type>
    <actuator>
      <name>rear_left_shoulder_motor</name>
      <mechanicalReduction>1</mechanicalReduction>
    </actuator>
    <joint>
      <name>rear_left_shoulder</name>
      <hardwareInterface>hardware_interface/Effort</hardwareInterface>
    </joint>
  </transmission>
  <transmission name="rear_left_leg_trans">
    <type>transmission_interface/SimpleTransmission</type>
    <actuator>
      <name>rear_left_leg_motor</name>
      <mechanicalReduction>1</mechanicalReduction>
    </actuator>
    <joint>
      <name>rear_left_leg</name>
      <hardwareInterface>hardware_interface/Effort</hardwareInterface>
    </joint>
  </transmission>
  <transmission name="rear_left_foot_trans">
    <type>transmission_interface/SimpleTransmission</type>
    <actuator>
      <name>rear_left_foot_motor</name>
      <mechanicalReduction>1</mechanicalReduction>
    </actuator>
    <joint>
      <name>rear_left_foot</name>
      <hardwareInterface>hardware_interface/Effort</hardwareInterface>
    </joint>
  </transmission>
  <transmission name="rear_right_shoulder_trans">
    <type>transmission_interface/SimpleTransmission</type>
    <actuator>
      <name>rear_right_shoulder_motor</name>
      <mechanicalReduction>1</mechanicalReduction>
    </actuator>
    <joint>
      <name>rear_right_shoulder</name>
      <hardwareInterface>hardware_interface/Effort</hardwareInterface>
    </joint>
  </transmission>
  <transmission name="rear_right_leg_trans">
    <type>transmission_interface/SimpleTransmission</type>
    <actuator>
      <name>rear_right_leg_motor</name>
      <mechanicalReduction>1</mechanicalReduction>
    </actuator>
    <joint>
      <name>rear_right_leg</name>
      <hardwareInterface>hardware_interface/Effort</hardwareInterface>
    </joint>
  </transmission>
  <transmission name="rear_right_foot_trans">
    <type>transmission_interface/SimpleTransmission</type>
    <actuator>
      <name>rear_right_foot_motor</name>
      <mechanicalReduction>1</mechanicalReduction>
    </actuator>
    <joint>
      <name>rear_right_foot</name>
      <hardwareInterface>hardware_interface/Effort</hardwareInterface>
    </joint>
  </transmission>
  <ros2_control name="servo_system" type="system">
    <hardware>
      <plugin>gz_ros2_control/GazeboSimSystem</plugin>
      <param name="use_sim_time">true</param>
    </hardware>
    <!-- Declaras todos los joints controlables -->
    <joint name="front_left_shoulder">
      <command_interface name="effort"/>
      <state_interface name="position"/>
      <state_interface name="velocity"/>
    </joint>
    <joint name="front_left_leg">
      <command_interface name="effort"/>
      <state_interface name="position"/>
      <state_interface name="velocity"/>
    </joint>
    <joint name="front_left_foot">
      <command_interface name="effort"/>
      <state_interface name="position"/>
      <state_interface name="velocity"/>
    </joint>
    <!-- Añade el resto de las patas -->
    <joint name="front_right_shoulder">
      <command_interface name="effort"/>
      <state_interface name="position"/>
      <state_interface name="velocity"/>
    </joint>
    <joint name="front_right_leg">
      <command_interface name="effort"/>
      <state_interface name="position"/>
      <state_interface name="velocity"/>
    </joint>
    <joint name="front_right_foot">
      <command_interface name="effort"/>
      <state_interface name="position"/>
      <state_interface name="velocity"/>
    </joint>
    <!-- Igual para las patas traseras -->
    <joint name="rear_left_shoulder">
      <command_interface name="effort"/>
      <state_interface name="position"/>
      <state_interface name="velocity"/>
    </joint>
    <joint name="rear_left_leg">
      <command_interface name="effort"/>
      <state_interface name="position"/>
      <state_interface name="velocity"/>
    </joint>
    <joint name="rear_left_foot">
      <command_interface name="effort"/>
      <state_interface name="position"/>
      <state_interface name="velocity"/>
    </joint>
    <joint name="rear_right_shoulder">
      <command_interface name="effort"/>
      <state_interface name="position"/>
      <state_interface name="velocity"/>
    </joint>
    <joint name="rear_right_leg">
      <command_interface name="effort"/>
      <state_interface name="position"/>
      <state_interface name="velocity"/>
    </joint>
    <joint name="rear_right_foot">
      <command_interface name="effort"/>
      <state_interface name="position"/>
      <state_interface name="velocity"/>
    </joint>
  </ros2_control>
  <gazebo>
    <plugin filename="libgz_ros2_control-system.so" name="gz_ros2_control::GazeboSimROS2ControlPlugin">
      <!-- Archivo YAML con los controladores PID -->
      <parameters>/home/johann/proyectos/Sentra/install/motor_controller/share/motor_controller/config/controllers.yaml</parameters>
    </plugin>
  </gazebo>
</robot>
